{
  "timestamp": "2025-10-17T10:01:14.713699",
  "raw_log_context": "2025/10/14 17:12:47 [notice] 1#1: cache loader process 43 exited with code 0\n2025/10/14 17:12:47 [notice] 1#1: signal 29 (SIGIO) received\n2025/10/14 17:12:10 [error] 35#35: *38 connect() failed (111: Connection refused) while connecting to upstream, client: 127.0.0.1, server: , request: \"GET /api/v1/settings/public/open/ HTTP/1.1\", upstream: \"http://192.168.250.7:8080/api/v1/settings/public/open/\", host: \"192.168.1.72\", referrer: \"http://192.168.1.72/ui/\"\n2025/10/14 17:12:10 [error] 35#35: *38 connect() failed (111: Connection refused) while connecting to upstream, client: 127.0.0.1, server: , request: \"GET /api/v1/settings/public/open/ HTTP/1.1\", upstream: \"http://192.168.250.7:8080/api/v1/settings/public/open/\", host: \"192.168.1.72\", referrer: \"http://192.168.1.72/ui/\"",
  "analysis": {
    "summary": "Nginx代理无法连接到上游服务192.168.250.7:8080，导致API请求失败",
    "severity": "高",
    "diagnosis_path": [
      "检查上游服务192.168.250.7:8080是否正常运行",
      "验证网络连通性（防火墙、路由、端口访问）",
      "检查Nginx upstream配置是否正确",
      "确认后端服务监听地址和端口绑定",
      "检查后端服务日志确认拒绝连接的具体原因"
    ],
    "solution": {
      "immediate": "重启上游服务或检查服务状态，临时调整Nginx upstream到备用节点",
      "long_term": "完善服务健康检查机制，实现负载均衡自动故障转移，加强监控告警"
    },
    "timestamp": "2025-10-17T10:01:14.713686"
  }
}